wandb: Currently logged in as: tychovdo (use `wandb login --relogin` to force relogin)
wandb: Tracking run with wandb version 0.12.10
wandb: Syncing run radiant-tree-4832
wandb: ‚≠êÔ∏è View project at https://wandb.ai/tychovdo/partial_equiv
wandb: üöÄ View run at https://wandb.ai/tychovdo/partial_equiv/runs/1ql8r6u5
wandb: Run data is saved locally in /tmp/pbs.5552415.pbs/outputs/2022-05-14/00-26-40/wandb/run-20220514_002641-1ql8r6u5
wandb: Run `wandb offline` to turn off syncing.
  0% 0/170498071 [00:00<?, ?it/s]  0% 33792/170498071 [00:00<15:25, 184116.41it/s]  0% 197632/170498071 [00:00<04:45, 596190.75it/s]  0% 775168/170498071 [00:00<01:16, 2213958.64it/s]  1% 1721344/170498071 [00:00<00:41, 4072293.07it/s]  2% 3474432/170498071 [00:00<00:23, 7150910.07it/s]  4% 6685696/170498071 [00:00<00:11, 13888489.13it/s]  6% 10257408/170498071 [00:00<00:08, 19958806.25it/s]  8% 13829120/170498071 [00:01<00:06, 24440530.97it/s] 10% 17400832/170498071 [00:01<00:05, 27695686.86it/s] 12% 20981760/170498071 [00:01<00:04, 30065687.62it/s] 14% 24478720/170498071 [00:01<00:05, 28549103.83it/s] 16% 27821056/170498071 [00:01<00:05, 28490026.88it/s] 18% 31340544/170498071 [00:01<00:04, 30320516.67it/s] 20% 34882560/170498071 [00:01<00:04, 31744972.27it/s] 23% 38454272/170498071 [00:01<00:04, 32873518.61it/s] 25% 42014720/170498071 [00:01<00:03, 33665600.10it/s] 27% 45597696/170498071 [00:01<00:03, 34295819.06it/s] 29% 49056768/170498071 [00:02<00:03, 31849563.58it/s] 31% 52495360/170498071 [00:02<00:03, 30833894.97it/s] 33% 56157184/170498071 [00:02<00:03, 32425463.38it/s] 35% 59444224/170498071 [00:02<00:03, 32017229.12it/s] 37% 62989312/170498071 [00:02<00:03, 32992157.71it/s] 39% 66552832/170498071 [00:02<00:03, 33471377.54it/s] 41% 70122496/170498071 [00:02<00:02, 34117018.76it/s] 43% 73550848/170498071 [00:02<00:02, 32337983.88it/s] 45% 76923904/170498071 [00:02<00:03, 31020330.54it/s] 47% 80364544/170498071 [00:03<00:02, 31478948.41it/s] 49% 83706880/170498071 [00:03<00:02, 31887007.35it/s] 51% 87255040/170498071 [00:03<00:02, 32911500.23it/s] 53% 90829824/170498071 [00:03<00:02, 33732812.67it/s] 55% 94388224/170498071 [00:03<00:02, 34274568.70it/s] 57% 97827840/170498071 [00:03<00:02, 32591149.99it/s] 59% 101295104/170498071 [00:03<00:02, 33185454.15it/s] 61% 104662016/170498071 [00:03<00:02, 32071385.35it/s] 63% 108069888/170498071 [00:03<00:01, 31312952.47it/s] 65% 111622144/170498071 [00:04<00:01, 32494891.26it/s] 68% 115164160/170498071 [00:04<00:01, 33330830.91it/s] 70% 118719488/170498071 [00:04<00:01, 33972052.06it/s] 72% 122160128/170498071 [00:04<00:01, 33901221.20it/s] 74% 125560832/170498071 [00:04<00:01, 33153228.66it/s] 76% 129008640/170498071 [00:04<00:01, 33447272.47it/s] 78% 132367360/170498071 [00:04<00:01, 32550428.61it/s] 80% 135660544/170498071 [00:04<00:01, 30791917.29it/s] 82% 139199488/170498071 [00:04<00:00, 32074248.07it/s] 84% 142779392/170498071 [00:04<00:00, 33138474.44it/s] 86% 146310144/170498071 [00:05<00:00, 33767062.23it/s] 88% 149704704/170498071 [00:05<00:00, 33796167.65it/s] 90% 153097216/170498071 [00:05<00:00, 33557801.73it/s] 92% 156462080/170498071 [00:05<00:00, 33543902.76it/s] 94% 159822848/170498071 [00:05<00:00, 33483016.12it/s] 96% 163175424/170498071 [00:05<00:00, 32751223.99it/s] 98% 166528000/170498071 [00:05<00:00, 31114046.51it/s]100% 169853952/170498071 [00:05<00:00, 31600241.33it/s]170499072it [00:05, 29258813.87it/s]                   
  0% 0/170498071 [00:00<?, ?it/s]  0% 33792/170498071 [00:00<15:32, 182861.48it/s]  0% 181248/170498071 [00:00<04:21, 650505.30it/s]  0% 427008/170498071 [00:00<02:32, 1111910.90it/s]  1% 1580032/170498071 [00:00<00:39, 4267785.20it/s]  2% 3175424/170498071 [00:00<00:21, 7797379.38it/s]  3% 5702656/170498071 [00:00<00:12, 13064011.70it/s]  5% 9201664/170498071 [00:00<00:08, 19663319.48it/s]  7% 12387328/170498071 [00:00<00:06, 22900126.45it/s]  9% 15778816/170498071 [00:01<00:06, 23064304.86it/s] 11% 19252224/170498071 [00:01<00:05, 26231979.93it/s] 13% 22774784/170498071 [00:01<00:05, 28739874.41it/s] 15% 26166272/170498071 [00:01<00:04, 30039537.01it/s] 17% 29672448/170498071 [00:01<00:04, 31477845.00it/s] 19% 33178624/170498071 [00:01<00:04, 32514765.52it/s] 22% 36717568/170498071 [00:01<00:04, 33358145.47it/s] 24% 40223744/170498071 [00:01<00:03, 33860190.52it/s] 26% 43632640/170498071 [00:01<00:04, 30318148.31it/s] 28% 47196160/170498071 [00:02<00:03, 31779942.89it/s] 30% 50463744/170498071 [00:02<00:03, 31940414.56it/s] 32% 53709824/170498071 [00:02<00:03, 32034861.58it/s] 33% 57099264/170498071 [00:02<00:03, 32255258.96it/s] 36% 60662784/170498071 [00:02<00:03, 33238595.49it/s] 38% 64243712/170498071 [00:02<00:03, 33992497.71it/s] 40% 67765248/170498071 [00:02<00:02, 34351262.37it/s] 42% 71213056/170498071 [00:02<00:03, 31709800.98it/s] 44% 74662912/170498071 [00:02<00:02, 32490427.41it/s] 46% 78077952/170498071 [00:02<00:02, 32965597.86it/s] 48% 81403904/170498071 [00:03<00:02, 31927856.81it/s] 50% 84837376/170498071 [00:03<00:02, 32418880.68it/s] 52% 88297472/170498071 [00:03<00:02, 33049134.12it/s] 54% 91837440/170498071 [00:03<00:02, 33735537.88it/s] 56% 95308800/170498071 [00:03<00:02, 34023250.29it/s] 58% 98765824/170498071 [00:03<00:02, 34184832.53it/s] 60% 102192128/170498071 [00:03<00:02, 32281148.24it/s] 62% 105513984/170498071 [00:03<00:01, 32547803.19it/s] 64% 108807168/170498071 [00:03<00:01, 32399848.77it/s] 66% 112231424/170498071 [00:04<00:01, 31661692.65it/s] 68% 115639296/170498071 [00:04<00:01, 32170016.14it/s] 70% 119137280/170498071 [00:04<00:01, 32980729.13it/s] 72% 122651648/170498071 [00:04<00:01, 33609042.69it/s] 74% 126206976/170498071 [00:04<00:01, 34170569.92it/s] 76% 129632256/170498071 [00:04<00:01, 33259648.79it/s] 78% 132968448/170498071 [00:04<00:01, 33201138.27it/s] 80% 136295424/170498071 [00:04<00:01, 33097793.79it/s] 82% 139625472/170498071 [00:04<00:00, 33022880.20it/s] 84% 142967808/170498071 [00:04<00:00, 32514382.13it/s] 86% 146223104/170498071 [00:05<00:00, 31746235.11it/s] 88% 149755904/170498071 [00:05<00:00, 32783810.94it/s] 90% 153256960/170498071 [00:05<00:00, 33411311.86it/s] 92% 156739584/170498071 [00:05<00:00, 33827311.33it/s] 94% 160128000/170498071 [00:05<00:00, 32698405.66it/s] 96% 163513344/170498071 [00:05<00:00, 32866418.61it/s] 98% 166855680/170498071 [00:05<00:00, 32920159.89it/s]100% 170181632/170498071 [00:05<00:00, 32909019.47it/s]170499072it [00:05, 29396006.50it/s]                   
/rds/general/user/tv21/home/anaconda3/lib/python3.9/site-packages/torch/functional.py:445: UserWarning: torch.meshgrid: in an upcoming release, it will be required to pass the indexing argument. (Triggered internally at  /opt/conda/conda-bld/pytorch_1640811803361/work/aten/src/ATen/native/TensorShape.cpp:2157.)
  return _VF.meshgrid(tensors, **kwargs)  # type: ignore[attr-defined]
--- Logging error ---
Traceback (most recent call last):
  File "/rds/general/user/tv21/home/anaconda3/lib/python3.9/logging/__init__.py", line 1087, in emit
    self.flush()
  File "/rds/general/user/tv21/home/anaconda3/lib/python3.9/logging/__init__.py", line 1067, in flush
    self.stream.flush()
OSError: [Errno 28] No space left on device
Call stack:
  File "/rds/general/user/tv21/home/anaconda3/lib/python3.9/threading.py", line 930, in _bootstrap
    self._bootstrap_inner()
  File "/rds/general/user/tv21/home/anaconda3/lib/python3.9/threading.py", line 973, in _bootstrap_inner
    self.run()
  File "/rds/general/user/tv21/home/anaconda3/lib/python3.9/site-packages/wandb/sdk/internal/internal_util.py", line 54, in run
    self._run()
  File "/rds/general/user/tv21/home/anaconda3/lib/python3.9/site-packages/wandb/sdk/internal/internal_util.py", line 105, in _run
    self._process(record)
  File "/rds/general/user/tv21/home/anaconda3/lib/python3.9/site-packages/wandb/sdk/internal/internal.py", line 260, in _process
    self._hm.handle(record)
  File "/rds/general/user/tv21/home/anaconda3/lib/python3.9/site-packages/wandb/sdk/internal/handler.py", line 123, in handle
    handler(record)
  File "/rds/general/user/tv21/home/anaconda3/lib/python3.9/site-packages/wandb/sdk/internal/handler.py", line 131, in handle_request
    logger.debug("handle_request: {}".format(request_type))
Message: 'handle_request: stop_status'
Arguments: ()
--- Logging error ---
Traceback (most recent call last):
  File "/rds/general/user/tv21/home/anaconda3/lib/python3.9/logging/__init__.py", line 1087, in emit
    self.flush()
  File "/rds/general/user/tv21/home/anaconda3/lib/python3.9/logging/__init__.py", line 1067, in flush
    self.stream.flush()
OSError: [Errno 28] No space left on device
Call stack:
  File "/rds/general/user/tv21/home/anaconda3/lib/python3.9/threading.py", line 930, in _bootstrap
    self._bootstrap_inner()
  File "/rds/general/user/tv21/home/anaconda3/lib/python3.9/threading.py", line 973, in _bootstrap_inner
    self.run()
  File "/rds/general/user/tv21/home/anaconda3/lib/python3.9/site-packages/wandb/sdk/internal/internal_util.py", line 54, in run
    self._run()
  File "/rds/general/user/tv21/home/anaconda3/lib/python3.9/site-packages/wandb/sdk/internal/internal_util.py", line 105, in _run
    self._process(record)
  File "/rds/general/user/tv21/home/anaconda3/lib/python3.9/site-packages/wandb/sdk/internal/internal.py", line 305, in _process
    self._sm.send(record)
  File "/rds/general/user/tv21/home/anaconda3/lib/python3.9/site-packages/wandb/sdk/internal/sender.py", line 237, in send
    send_handler(record)
  File "/rds/general/user/tv21/home/anaconda3/lib/python3.9/site-packages/wandb/sdk/internal/sender.py", line 249, in send_request
    logger.debug("send_request: {}".format(request_type))
Message: 'send_request: stop_status'
Arguments: ()
--- Logging error ---
Traceback (most recent call last):
  File "/rds/general/user/tv21/home/anaconda3/lib/python3.9/logging/__init__.py", line 1087, in emit
    self.flush()
  File "/rds/general/user/tv21/home/anaconda3/lib/python3.9/logging/__init__.py", line 1067, in flush
    self.stream.flush()
OSError: [Errno 28] No space left on device
Call stack:
  File "/rds/general/user/tv21/home/anaconda3/lib/python3.9/threading.py", line 930, in _bootstrap
    self._bootstrap_inner()
  File "/rds/general/user/tv21/home/anaconda3/lib/python3.9/threading.py", line 973, in _bootstrap_inner
    self.run()
  File "/rds/general/user/tv21/home/anaconda3/lib/python3.9/site-packages/wandb/sdk/internal/internal_util.py", line 54, in run
    self._run()
  File "/rds/general/user/tv21/home/anaconda3/lib/python3.9/site-packages/wandb/sdk/internal/internal_util.py", line 105, in _run
    self._process(record)
  File "/rds/general/user/tv21/home/anaconda3/lib/python3.9/site-packages/wandb/sdk/internal/internal.py", line 260, in _process
    self._hm.handle(record)
  File "/rds/general/user/tv21/home/anaconda3/lib/python3.9/site-packages/wandb/sdk/internal/handler.py", line 123, in handle
    handler(record)
  File "/rds/general/user/tv21/home/anaconda3/lib/python3.9/site-packages/wandb/sdk/internal/handler.py", line 131, in handle_request
    logger.debug("handle_request: {}".format(request_type))
Message: 'handle_request: stop_status'
Arguments: ()
--- Logging error ---
Traceback (most recent call last):
  File "/rds/general/user/tv21/home/anaconda3/lib/python3.9/logging/__init__.py", line 1087, in emit
    self.flush()
  File "/rds/general/user/tv21/home/anaconda3/lib/python3.9/logging/__init__.py", line 1067, in flush
    self.stream.flush()
OSError: [Errno 28] No space left on device
Call stack:
  File "/rds/general/user/tv21/home/anaconda3/lib/python3.9/threading.py", line 930, in _bootstrap
    self._bootstrap_inner()
  File "/rds/general/user/tv21/home/anaconda3/lib/python3.9/threading.py", line 973, in _bootstrap_inner
    self.run()
  File "/rds/general/user/tv21/home/anaconda3/lib/python3.9/site-packages/wandb/sdk/internal/internal_util.py", line 54, in run
    self._run()
  File "/rds/general/user/tv21/home/anaconda3/lib/python3.9/site-packages/wandb/sdk/internal/internal_util.py", line 105, in _run
    self._process(record)
  File "/rds/general/user/tv21/home/anaconda3/lib/python3.9/site-packages/wandb/sdk/internal/internal.py", line 305, in _process
    self._sm.send(record)
  File "/rds/general/user/tv21/home/anaconda3/lib/python3.9/site-packages/wandb/sdk/internal/sender.py", line 237, in send
    send_handler(record)
  File "/rds/general/user/tv21/home/anaconda3/lib/python3.9/site-packages/wandb/sdk/internal/sender.py", line 249, in send_request
    logger.debug("send_request: {}".format(request_type))
Message: 'send_request: stop_status'
Arguments: ()
--- Logging error ---
Traceback (most recent call last):
  File "/rds/general/user/tv21/home/anaconda3/lib/python3.9/logging/__init__.py", line 1087, in emit
    self.flush()
  File "/rds/general/user/tv21/home/anaconda3/lib/python3.9/logging/__init__.py", line 1067, in flush
    self.stream.flush()
OSError: [Errno 28] No space left on device
Call stack:
  File "/rds/general/user/tv21/home/anaconda3/lib/python3.9/threading.py", line 930, in _bootstrap
    self._bootstrap_inner()
  File "/rds/general/user/tv21/home/anaconda3/lib/python3.9/threading.py", line 973, in _bootstrap_inner
    self.run()
  File "/rds/general/user/tv21/home/anaconda3/lib/python3.9/site-packages/wandb/sdk/internal/internal_util.py", line 54, in run
    self._run()
  File "/rds/general/user/tv21/home/anaconda3/lib/python3.9/site-packages/wandb/sdk/internal/internal_util.py", line 105, in _run
    self._process(record)
  File "/rds/general/user/tv21/home/anaconda3/lib/python3.9/site-packages/wandb/sdk/internal/internal.py", line 305, in _process
    self._sm.send(record)
  File "/rds/general/user/tv21/home/anaconda3/lib/python3.9/site-packages/wandb/sdk/internal/sender.py", line 235, in send
    logger.debug("send: {}".format(record_type))
Message: 'send: stats'
Arguments: ()
--- Logging error ---
Traceback (most recent call last):
  File "/rds/general/user/tv21/home/anaconda3/lib/python3.9/logging/__init__.py", line 1087, in emit
    self.flush()
  File "/rds/general/user/tv21/home/anaconda3/lib/python3.9/logging/__init__.py", line 1067, in flush
    self.stream.flush()
OSError: [Errno 28] No space left on device
Call stack:
  File "/rds/general/user/tv21/home/anaconda3/lib/python3.9/threading.py", line 930, in _bootstrap
    self._bootstrap_inner()
  File "/rds/general/user/tv21/home/anaconda3/lib/python3.9/threading.py", line 973, in _bootstrap_inner
    self.run()
  File "/rds/general/user/tv21/home/anaconda3/lib/python3.9/site-packages/wandb/sdk/internal/internal_util.py", line 54, in run
    self._run()
  File "/rds/general/user/tv21/home/anaconda3/lib/python3.9/site-packages/wandb/sdk/internal/internal_util.py", line 105, in _run
    self._process(record)
  File "/rds/general/user/tv21/home/anaconda3/lib/python3.9/site-packages/wandb/sdk/internal/internal.py", line 260, in _process
    self._hm.handle(record)
  File "/rds/general/user/tv21/home/anaconda3/lib/python3.9/site-packages/wandb/sdk/internal/handler.py", line 123, in handle
    handler(record)
  File "/rds/general/user/tv21/home/anaconda3/lib/python3.9/site-packages/wandb/sdk/internal/handler.py", line 131, in handle_request
    logger.debug("handle_request: {}".format(request_type))
Message: 'handle_request: stop_status'
Arguments: ()
--- Logging error ---
Traceback (most recent call last):
  File "/rds/general/user/tv21/home/anaconda3/lib/python3.9/logging/__init__.py", line 1087, in emit
    self.flush()
  File "/rds/general/user/tv21/home/anaconda3/lib/python3.9/logging/__init__.py", line 1067, in flush
    self.stream.flush()
OSError: [Errno 28] No space left on device
Call stack:
  File "/rds/general/user/tv21/home/anaconda3/lib/python3.9/threading.py", line 930, in _bootstrap
    self._bootstrap_inner()
  File "/rds/general/user/tv21/home/anaconda3/lib/python3.9/threading.py", line 973, in _bootstrap_inner
    self.run()
  File "/rds/general/user/tv21/home/anaconda3/lib/python3.9/site-packages/wandb/sdk/internal/internal_util.py", line 54, in run
    self._run()
  File "/rds/general/user/tv21/home/anaconda3/lib/python3.9/site-packages/wandb/sdk/internal/internal_util.py", line 105, in _run
    self._process(record)
  File "/rds/general/user/tv21/home/anaconda3/lib/python3.9/site-packages/wandb/sdk/internal/internal.py", line 305, in _process
    self._sm.send(record)
  File "/rds/general/user/tv21/home/anaconda3/lib/python3.9/site-packages/wandb/sdk/internal/sender.py", line 237, in send
    send_handler(record)
  File "/rds/general/user/tv21/home/anaconda3/lib/python3.9/site-packages/wandb/sdk/internal/sender.py", line 249, in send_request
    logger.debug("send_request: {}".format(request_type))
Message: 'send_request: stop_status'
Arguments: ()
--- Logging error ---
Traceback (most recent call last):
  File "/rds/general/user/tv21/home/anaconda3/lib/python3.9/logging/__init__.py", line 1087, in emit
    self.flush()
  File "/rds/general/user/tv21/home/anaconda3/lib/python3.9/logging/__init__.py", line 1067, in flush
    self.stream.flush()
OSError: [Errno 28] No space left on device
Call stack:
  File "/rds/general/user/tv21/home/anaconda3/lib/python3.9/threading.py", line 930, in _bootstrap
    self._bootstrap_inner()
  File "/rds/general/user/tv21/home/anaconda3/lib/python3.9/threading.py", line 973, in _bootstrap_inner
    self.run()
  File "/rds/general/user/tv21/home/anaconda3/lib/python3.9/site-packages/wandb/sdk/internal/internal_util.py", line 54, in run
    self._run()
  File "/rds/general/user/tv21/home/anaconda3/lib/python3.9/site-packages/wandb/sdk/internal/internal_util.py", line 106, in _run
    self._finish()
  File "/rds/general/user/tv21/home/anaconda3/lib/python3.9/site-packages/wandb/sdk/internal/internal.py", line 308, in _finish
    self._sm.finish()
  File "/rds/general/user/tv21/home/anaconda3/lib/python3.9/site-packages/wandb/sdk/internal/sender.py", line 1079, in finish
    self._dir_watcher.finish()
  File "/rds/general/user/tv21/home/anaconda3/lib/python3.9/site-packages/wandb/filesync/dir_watcher.py", line 327, in finish
    logger.info("scan save: %s %s", file_path, save_name)
Message: 'scan save: %s %s'
Arguments: ('/tmp/pbs.5552415.pbs/outputs/2022-05-14/00-26-40/wandb/run-20220514_002641-1ql8r6u5/files/config.yaml', 'config.yaml')
--- Logging error ---
Traceback (most recent call last):
  File "/rds/general/user/tv21/home/anaconda3/lib/python3.9/logging/__init__.py", line 1087, in emit
    self.flush()
  File "/rds/general/user/tv21/home/anaconda3/lib/python3.9/logging/__init__.py", line 1067, in flush
    self.stream.flush()
OSError: [Errno 28] No space left on device
Call stack:
  File "/rds/general/user/tv21/home/anaconda3/lib/python3.9/threading.py", line 930, in _bootstrap
    self._bootstrap_inner()
  File "/rds/general/user/tv21/home/anaconda3/lib/python3.9/threading.py", line 973, in _bootstrap_inner
    self.run()
  File "/rds/general/user/tv21/home/anaconda3/lib/python3.9/site-packages/wandb/sdk/internal/internal_util.py", line 54, in run
    self._run()
  File "/rds/general/user/tv21/home/anaconda3/lib/python3.9/site-packages/wandb/sdk/internal/internal_util.py", line 106, in _run
    self._finish()
  File "/rds/general/user/tv21/home/anaconda3/lib/python3.9/site-packages/wandb/sdk/internal/internal.py", line 308, in _finish
    self._sm.finish()
  File "/rds/general/user/tv21/home/anaconda3/lib/python3.9/site-packages/wandb/sdk/internal/sender.py", line 1082, in finish
    self._pusher.finish()
  File "/rds/general/user/tv21/home/anaconda3/lib/python3.9/site-packages/wandb/sdk/internal/file_pusher.py", line 177, in finish
    logger.info("shutting down file pusher")
Message: 'shutting down file pusher'
Arguments: ()
--- Logging error ---
Traceback (most recent call last):
  File "/rds/general/user/tv21/home/anaconda3/lib/python3.9/logging/__init__.py", line 1087, in emit
    self.flush()
  File "/rds/general/user/tv21/home/anaconda3/lib/python3.9/logging/__init__.py", line 1067, in flush
    self.stream.flush()
OSError: [Errno 28] No space left on device
Call stack:
  File "/rds/general/user/tv21/home/anaconda3/lib/python3.9/threading.py", line 930, in _bootstrap
    self._bootstrap_inner()
  File "/rds/general/user/tv21/home/anaconda3/lib/python3.9/threading.py", line 973, in _bootstrap_inner
    self.run()
  File "/rds/general/user/tv21/home/anaconda3/lib/python3.9/site-packages/wandb/sdk/internal/internal_util.py", line 54, in run
    self._run()
  File "/rds/general/user/tv21/home/anaconda3/lib/python3.9/site-packages/wandb/sdk/internal/internal_util.py", line 106, in _run
    self._finish()
  File "/rds/general/user/tv21/home/anaconda3/lib/python3.9/site-packages/wandb/sdk/internal/internal.py", line 308, in _finish
    self._sm.finish()
  File "/rds/general/user/tv21/home/anaconda3/lib/python3.9/site-packages/wandb/sdk/internal/sender.py", line 1083, in finish
    self._pusher.join()
  File "/rds/general/user/tv21/home/anaconda3/lib/python3.9/site-packages/wandb/sdk/internal/file_pusher.py", line 182, in join
    logger.info("waiting for file pusher")
Message: 'waiting for file pusher'
Arguments: ()
--- Logging error ---
Traceback (most recent call last):
  File "/rds/general/user/tv21/home/anaconda3/lib/python3.9/logging/__init__.py", line 1087, in emit
    self.flush()
  File "/rds/general/user/tv21/home/anaconda3/lib/python3.9/logging/__init__.py", line 1067, in flush
    self.stream.flush()
OSError: [Errno 28] No space left on device
Call stack:
  File "/rds/general/user/tv21/home/anaconda3/lib/python3.9/threading.py", line 930, in _bootstrap
    self._bootstrap_inner()
  File "/rds/general/user/tv21/home/anaconda3/lib/python3.9/threading.py", line 973, in _bootstrap_inner
    self.run()
  File "/rds/general/user/tv21/home/anaconda3/lib/python3.9/site-packages/wandb/filesync/upload_job.py", line 56, in run
    success = self.push()
  File "/rds/general/user/tv21/home/anaconda3/lib/python3.9/site-packages/wandb/filesync/upload_job.py", line 137, in push
    logger.info("Uploaded file %s", self.save_path)
Message: 'Uploaded file %s'
Arguments: ('/tmp/pbs.5552415.pbs/outputs/2022-05-14/00-26-40/wandb/run-20220514_002641-1ql8r6u5/files/requirements.txt',)
--- Logging error ---
Traceback (most recent call last):
  File "/rds/general/user/tv21/home/anaconda3/lib/python3.9/logging/__init__.py", line 1087, in emit
    self.flush()
  File "/rds/general/user/tv21/home/anaconda3/lib/python3.9/logging/__init__.py", line 1067, in flush
    self.stream.flush()
OSError: [Errno 28] No space left on device
Call stack:
  File "/rds/general/user/tv21/home/anaconda3/lib/python3.9/threading.py", line 930, in _bootstrap
    self._bootstrap_inner()
  File "/rds/general/user/tv21/home/anaconda3/lib/python3.9/threading.py", line 973, in _bootstrap_inner
    self.run()
  File "/rds/general/user/tv21/home/anaconda3/lib/python3.9/site-packages/wandb/filesync/upload_job.py", line 56, in run
    success = self.push()
  File "/rds/general/user/tv21/home/anaconda3/lib/python3.9/site-packages/wandb/filesync/upload_job.py", line 137, in push
    logger.info("Uploaded file %s", self.save_path)
Message: 'Uploaded file %s'
Arguments: ('/tmp/pbs.5552415.pbs/outputs/2022-05-14/00-26-40/wandb/run-20220514_002641-1ql8r6u5/files/output.log',)
--- Logging error ---
Traceback (most recent call last):
  File "/rds/general/user/tv21/home/anaconda3/lib/python3.9/logging/__init__.py", line 1087, in emit
    self.flush()
  File "/rds/general/user/tv21/home/anaconda3/lib/python3.9/logging/__init__.py", line 1067, in flush
    self.stream.flush()
OSError: [Errno 28] No space left on device
Call stack:
  File "/rds/general/user/tv21/home/anaconda3/lib/python3.9/threading.py", line 930, in _bootstrap
    self._bootstrap_inner()
  File "/rds/general/user/tv21/home/anaconda3/lib/python3.9/threading.py", line 973, in _bootstrap_inner
    self.run()
  File "/rds/general/user/tv21/home/anaconda3/lib/python3.9/site-packages/wandb/filesync/upload_job.py", line 56, in run
    success = self.push()
  File "/rds/general/user/tv21/home/anaconda3/lib/python3.9/site-packages/wandb/filesync/upload_job.py", line 137, in push
    logger.info("Uploaded file %s", self.save_path)
Message: 'Uploaded file %s'
Arguments: ('/tmp/pbs.5552415.pbs/outputs/2022-05-14/00-26-40/wandb/run-20220514_002641-1ql8r6u5/files/wandb-summary.json',)
--- Logging error ---
Traceback (most recent call last):
  File "/rds/general/user/tv21/home/anaconda3/lib/python3.9/logging/__init__.py", line 1087, in emit
    self.flush()
  File "/rds/general/user/tv21/home/anaconda3/lib/python3.9/logging/__init__.py", line 1067, in flush
    self.stream.flush()
OSError: [Errno 28] No space left on device
Call stack:
  File "/rds/general/user/tv21/home/anaconda3/lib/python3.9/threading.py", line 930, in _bootstrap
    self._bootstrap_inner()
  File "/rds/general/user/tv21/home/anaconda3/lib/python3.9/threading.py", line 973, in _bootstrap_inner
    self.run()
  File "/rds/general/user/tv21/home/anaconda3/lib/python3.9/site-packages/wandb/filesync/upload_job.py", line 56, in run
    success = self.push()
  File "/rds/general/user/tv21/home/anaconda3/lib/python3.9/site-packages/wandb/filesync/upload_job.py", line 137, in push
    logger.info("Uploaded file %s", self.save_path)
Message: 'Uploaded file %s'
Arguments: ('/tmp/pbs.5552415.pbs/outputs/2022-05-14/00-26-40/wandb/run-20220514_002641-1ql8r6u5/files/config.yaml',)
--- Logging error ---
Traceback (most recent call last):
  File "/rds/general/user/tv21/home/anaconda3/lib/python3.9/logging/__init__.py", line 1087, in emit
    self.flush()
  File "/rds/general/user/tv21/home/anaconda3/lib/python3.9/logging/__init__.py", line 1067, in flush
    self.stream.flush()
OSError: [Errno 28] No space left on device
Call stack:
  File "<string>", line 1, in <module>
  File "/rds/general/user/tv21/home/anaconda3/lib/python3.9/multiprocessing/spawn.py", line 116, in spawn_main
    exitcode = _main(fd, parent_sentinel)
  File "/rds/general/user/tv21/home/anaconda3/lib/python3.9/multiprocessing/spawn.py", line 129, in _main
    return self._bootstrap(parent_sentinel)
  File "/rds/general/user/tv21/home/anaconda3/lib/python3.9/multiprocessing/process.py", line 315, in _bootstrap
    self.run()
  File "/rds/general/user/tv21/home/anaconda3/lib/python3.9/multiprocessing/process.py", line 108, in run
    self._target(*self._args, **self._kwargs)
  File "/rds/general/user/tv21/home/anaconda3/lib/python3.9/site-packages/wandb/sdk/internal/internal.py", line 164, in wandb_internal
    logger.error("Thread {}:".format(thread.name), exc_info=exc_info)
Message: 'Thread WriterThread:'
Arguments: ()
Thread WriterThread:
Traceback (most recent call last):
  File "/rds/general/user/tv21/home/anaconda3/lib/python3.9/site-packages/wandb/sdk/internal/internal_util.py", line 54, in run
    self._run()
  File "/rds/general/user/tv21/home/anaconda3/lib/python3.9/site-packages/wandb/sdk/internal/internal_util.py", line 105, in _run
    self._process(record)
  File "/rds/general/user/tv21/home/anaconda3/lib/python3.9/site-packages/wandb/sdk/internal/internal.py", line 346, in _process
    self._wm.write(record)
  File "/rds/general/user/tv21/home/anaconda3/lib/python3.9/site-packages/wandb/sdk/internal/writer.py", line 35, in write
    self._ds.write(record)
  File "/rds/general/user/tv21/home/anaconda3/lib/python3.9/site-packages/wandb/sdk/internal/datastore.py", line 276, in write
    ret = self._write_data(s)
  File "/rds/general/user/tv21/home/anaconda3/lib/python3.9/site-packages/wandb/sdk/internal/datastore.py", line 236, in _write_data
    self._write_record(s)
  File "/rds/general/user/tv21/home/anaconda3/lib/python3.9/site-packages/wandb/sdk/internal/datastore.py", line 213, in _write_record
    self._fp.write(s)
OSError: [Errno 28] No space left on device
wandb: ERROR Internal wandb error: file data was not synced
--- Logging error ---
Traceback (most recent call last):
  File "/rds/general/user/tv21/home/anaconda3/lib/python3.9/logging/__init__.py", line 1087, in emit
    self.flush()
  File "/rds/general/user/tv21/home/anaconda3/lib/python3.9/logging/__init__.py", line 1067, in flush
    self.stream.flush()
OSError: [Errno 28] No space left on device
Call stack:
  File "/rds/general/user/tv21/home/anaconda3/lib/python3.9/site-packages/wandb/sdk/internal/internal.py", line 79, in handle_exit
    logger.info("Internal process exited")
Message: 'Internal process exited'
Arguments: ()
Exception in thread NetStatThr:
Traceback (most recent call last):
  File "/rds/general/user/tv21/home/anaconda3/lib/python3.9/threading.py", line 973, in _bootstrap_inner
    self.run()
  File "/rds/general/user/tv21/home/anaconda3/lib/python3.9/threading.py", line 910, in run
    self._target(*self._args, **self._kwargs)
  File "/rds/general/user/tv21/home/anaconda3/lib/python3.9/site-packages/wandb/sdk/wandb_run.py", line 148, in check_network_status
    status_response = self._interface.communicate_network_status()
  File "/rds/general/user/tv21/home/anaconda3/lib/python3.9/site-packages/wandb/sdk/interface/interface.py", line 125, in communicate_network_status
    resp = self._communicate_network_status(status)
  File "/rds/general/user/tv21/home/anaconda3/lib/python3.9/site-packages/wandb/sdk/interface/interface_shared.py", line 388, in _communicate_network_status
    resp = self._communicate(req, local=True)
  File "/rds/general/user/tv21/home/anaconda3/lib/python3.9/site-packages/wandb/sdk/interface/interface_shared.py", line 213, in _communicate
    return self._communicate_async(rec, local=local).get(timeout=timeout)
  File "/rds/general/user/tv21/home/anaconda3/lib/python3.9/site-packages/wandb/sdk/interface/interface_shared.py", line 218, in _communicate_async
    raise Exception("The wandb backend process has shutdown")
Exception: The wandb backend process has shutdown
Exception in thread ChkStopThr:
Traceback (most recent call last):
  File "/rds/general/user/tv21/home/anaconda3/lib/python3.9/threading.py", line 973, in _bootstrap_inner
    self.run()
  File "/rds/general/user/tv21/home/anaconda3/lib/python3.9/threading.py", line 910, in run
    self._target(*self._args, **self._kwargs)
  File "/rds/general/user/tv21/home/anaconda3/lib/python3.9/site-packages/wandb/sdk/wandb_run.py", line 166, in check_status
    status_response = self._interface.communicate_stop_status()
  File "/rds/general/user/tv21/home/anaconda3/lib/python3.9/site-packages/wandb/sdk/interface/interface.py", line 114, in communicate_stop_status
    resp = self._communicate_stop_status(status)
  File "/rds/general/user/tv21/home/anaconda3/lib/python3.9/site-packages/wandb/sdk/interface/interface_shared.py", line 378, in _communicate_stop_status
    resp = self._communicate(req, local=True)
  File "/rds/general/user/tv21/home/anaconda3/lib/python3.9/site-packages/wandb/sdk/interface/interface_shared.py", line 213, in _communicate
    return self._communicate_async(rec, local=local).get(timeout=timeout)
  File "/rds/general/user/tv21/home/anaconda3/lib/python3.9/site-packages/wandb/sdk/interface/interface_shared.py", line 218, in _communicate_async
    raise Exception("The wandb backend process has shutdown")
Exception: The wandb backend process has shutdown
[34m[1mwandb[0m: [33mWARNING[0m Saving files without folders. If you want to preserve sub directories pass base_path to wandb.save, i.e. wandb.save("/mnt/folder/file.h5", base_path="/mnt")
Error executing job with overrides: ['base_group.name=SE2', 'base_group.no_samples=4', 'base_group.sample_per_batch_element=False', 'base_group.sample_per_layer=True', 'base_group.sampling_method=random', 'conv.bias=True', 'conv.padding=same', 'conv.cond_rot=True', 'dataset=CIFAR10', 'kernel.learn_omega0=False', 'kernel.no_hidden=64', 'kernel.no_layers=3', 'kernel.omega0=10', 'kernel.learn_omega1=False', 'kernel.omega1=10', 'kernel.size=7', 'kernel.type=SIREN', 'kernel.weight_norm=False', 'net.dropout=0', 'net.no_blocks=2', 'net.no_hidden=32', 'net.norm=BatchNorm', 'net.pool_blocks=[1,2]', 'net.block_width_factors=[1,1,2,1]', 'net.type=CKResNet', 'no_workers=3', 'seed=100', 'train.batch_size=64', 'train.do=True', 'train.epochs=300', 'train.lr=0.001', 'train.scheduler=cosine', 'train.scheduler_params.warmup_epochs=5', 'train.weight_decay=0.0', 'train.lr_probs=1e-4', 'kernel.fix_integer=True']
Traceback (most recent call last):
  File "/rds/general/user/tv21/home/partial-equivariance/main.py", line 97, in main
    trainer.train(model, dataloaders, cfg)
  File "/rds/general/user/tv21/home/partial-equivariance/trainer.py", line 48, in train
    train_function(
  File "/rds/general/user/tv21/home/partial-equivariance/trainer.py", line 205, in classification_train
    save_model_to_wandb(model, optimizer, lr_scheduler, epoch=epoch + 1)
  File "/rds/general/user/tv21/home/partial-equivariance/trainer.py", line 303, in save_model_to_wandb
    wandb.save(path)
  File "/rds/general/user/tv21/home/anaconda3/lib/python3.9/site-packages/wandb/sdk/wandb_run.py", line 1442, in save
    self._backend.interface.publish_files(files_dict)
  File "/rds/general/user/tv21/home/anaconda3/lib/python3.9/site-packages/wandb/sdk/interface/interface.py", line 350, in publish_files
    self._publish_files(files)
  File "/rds/general/user/tv21/home/anaconda3/lib/python3.9/site-packages/wandb/sdk/interface/interface_shared.py", line 326, in _publish_files
    self._publish(rec)
  File "/rds/general/user/tv21/home/anaconda3/lib/python3.9/site-packages/wandb/sdk/interface/interface_queue.py", line 49, in _publish
    raise Exception("The wandb backend process has shutdown")
Exception: The wandb backend process has shutdown

Set the environment variable HYDRA_FULL_ERROR=1 for a complete stack trace.
Error in atexit._run_exitfuncs:
Traceback (most recent call last):
  File "/rds/general/user/tv21/home/anaconda3/lib/python3.9/site-packages/wandb/sdk/wandb_run.py", line 1805, in _atexit_cleanup
    self._on_finish()
  File "/rds/general/user/tv21/home/anaconda3/lib/python3.9/site-packages/wandb/sdk/wandb_run.py", line 1951, in _on_finish
    self.history._flush()
  File "/rds/general/user/tv21/home/anaconda3/lib/python3.9/site-packages/wandb/sdk/wandb_history.py", line 59, in _flush
    self._callback(row=self._data, step=self._step)
  File "/rds/general/user/tv21/home/anaconda3/lib/python3.9/site-packages/wandb/sdk/wandb_run.py", line 1027, in _history_callback
    self._backend.interface.publish_history(
  File "/rds/general/user/tv21/home/anaconda3/lib/python3.9/site-packages/wandb/sdk/interface/interface.py", line 506, in publish_history
    self._publish_history(history)
  File "/rds/general/user/tv21/home/anaconda3/lib/python3.9/site-packages/wandb/sdk/interface/interface_shared.py", line 59, in _publish_history
    self._publish(rec)
  File "/rds/general/user/tv21/home/anaconda3/lib/python3.9/site-packages/wandb/sdk/interface/interface_queue.py", line 49, in _publish
    raise Exception("The wandb backend process has shutdown")
Exception: The wandb backend process has shutdown

During handling of the above exception, another exception occurred:

Traceback (most recent call last):
  File "/rds/general/user/tv21/home/anaconda3/lib/python3.9/site-packages/wandb/sdk/wandb_run.py", line 1814, in _atexit_cleanup
    self._backend.cleanup()
  File "/rds/general/user/tv21/home/anaconda3/lib/python3.9/site-packages/wandb/sdk/backend/backend.py", line 248, in cleanup
    self.interface.join()
  File "/rds/general/user/tv21/home/anaconda3/lib/python3.9/site-packages/wandb/sdk/interface/interface_shared.py", line 458, in join
    super().join()
  File "/rds/general/user/tv21/home/anaconda3/lib/python3.9/site-packages/wandb/sdk/interface/interface.py", line 599, in join
    _ = self._communicate_shutdown()
  File "/rds/general/user/tv21/home/anaconda3/lib/python3.9/site-packages/wandb/sdk/interface/interface_shared.py", line 455, in _communicate_shutdown
    _ = self._communicate(record)
  File "/rds/general/user/tv21/home/anaconda3/lib/python3.9/site-packages/wandb/sdk/interface/interface_shared.py", line 213, in _communicate
    return self._communicate_async(rec, local=local).get(timeout=timeout)
  File "/rds/general/user/tv21/home/anaconda3/lib/python3.9/site-packages/wandb/sdk/interface/interface_shared.py", line 218, in _communicate_async
    raise Exception("The wandb backend process has shutdown")
Exception: The wandb backend process has shutdown
